[2021-04-07 03:00:01,242] {taskinstance.py:851} INFO - Dependencies all met for <TaskInstance: trata_relatorios.popula_relatorios 2021-04-07T02:50:00+00:00 [queued]>
[2021-04-07 03:00:01,337] {taskinstance.py:851} INFO - Dependencies all met for <TaskInstance: trata_relatorios.popula_relatorios 2021-04-07T02:50:00+00:00 [queued]>
[2021-04-07 03:00:01,340] {taskinstance.py:1042} INFO - 
--------------------------------------------------------------------------------
[2021-04-07 03:00:01,341] {taskinstance.py:1043} INFO - Starting attempt 1 of 1
[2021-04-07 03:00:01,341] {taskinstance.py:1044} INFO - 
--------------------------------------------------------------------------------
[2021-04-07 03:00:01,393] {taskinstance.py:1063} INFO - Executing <Task(PythonOperator): popula_relatorios> on 2021-04-07T02:50:00+00:00
[2021-04-07 03:00:01,404] {standard_task_runner.py:52} INFO - Started process 11320 to run task
[2021-04-07 03:00:01,412] {standard_task_runner.py:76} INFO - Running: ['airflow', 'tasks', 'run', 'trata_relatorios', 'popula_relatorios', '2021-04-07T02:50:00+00:00', '--job-id', '21', '--pool', 'default_pool', '--raw', '--subdir', 'DAGS_FOLDER/etl_chamados.py', '--cfg-path', '/tmp/tmpb1d3wkpp', '--error-file', '/tmp/tmpm6282dfn']
[2021-04-07 03:00:01,419] {standard_task_runner.py:77} INFO - Job 21: Subtask popula_relatorios
[2021-04-07 03:00:01,585] {logging_mixin.py:104} INFO - Running <TaskInstance: trata_relatorios.popula_relatorios 2021-04-07T02:50:00+00:00 [running]> on host ce03b876977a
[2021-04-07 03:00:01,768] {taskinstance.py:1257} INFO - Exporting the following env vars:
AIRFLOW_CTX_DAG_EMAIL=clecio.antao@gmail.com
AIRFLOW_CTX_DAG_OWNER=airflow
AIRFLOW_CTX_DAG_ID=trata_relatorios
AIRFLOW_CTX_TASK_ID=popula_relatorios
AIRFLOW_CTX_EXECUTION_DATE=2021-04-07T02:50:00+00:00
AIRFLOW_CTX_DAG_RUN_ID=scheduled__2021-04-07T02:50:00+00:00
[2021-04-07 03:00:12,411] {logging_mixin.py:104} INFO - Total de linhas:  5000
[2021-04-07 03:00:12,411] {logging_mixin.py:104} INFO - dGVjYmFu#b6abe415ebb4d31fc26cfdaccdb9eadace83afd9
[2021-04-07 03:00:12,412] {logging_mixin.py:104} INFO - entrou no laço
[2021-04-07 03:00:12,412] {logging_mixin.py:104} INFO - Paginas:  100000
[2021-04-07 03:00:12,413] {logging_mixin.py:104} INFO - Contador:  1
[2021-04-07 03:00:12,413] {logging_mixin.py:104} INFO - Linhas:  0
[2021-04-07 03:00:12,413] {logging_mixin.py:104} INFO - Colunas:  33
[2021-04-07 03:01:18,317] {logging_mixin.py:104} INFO - entrou no laço
[2021-04-07 03:01:18,320] {logging_mixin.py:104} INFO - Paginas:  100000
[2021-04-07 03:01:18,321] {logging_mixin.py:104} INFO - Contador:  2
[2021-04-07 03:01:18,321] {logging_mixin.py:104} INFO - Linhas:  5000
[2021-04-07 03:01:18,322] {logging_mixin.py:104} INFO - Colunas:  33
[2021-04-07 03:01:55,421] {logging_mixin.py:104} INFO - entrou no laço
[2021-04-07 03:01:55,421] {logging_mixin.py:104} INFO - Paginas:  100000
[2021-04-07 03:01:55,422] {logging_mixin.py:104} INFO - Contador:  3
[2021-04-07 03:01:55,422] {logging_mixin.py:104} INFO - Linhas:  10000
[2021-04-07 03:01:55,423] {logging_mixin.py:104} INFO - Colunas:  33
[2021-04-07 03:02:36,926] {logging_mixin.py:104} INFO - entrou no laço
[2021-04-07 03:02:36,930] {logging_mixin.py:104} INFO - Paginas:  100000
[2021-04-07 03:02:36,931] {logging_mixin.py:104} INFO - Contador:  4
[2021-04-07 03:02:36,932] {logging_mixin.py:104} INFO - Linhas:  15000
[2021-04-07 03:02:36,932] {logging_mixin.py:104} INFO - Colunas:  33
[2021-04-07 03:03:16,441] {logging_mixin.py:104} INFO - entrou no laço
[2021-04-07 03:03:16,442] {logging_mixin.py:104} INFO - Paginas:  100000
[2021-04-07 03:03:16,442] {logging_mixin.py:104} INFO - Contador:  5
[2021-04-07 03:03:16,447] {logging_mixin.py:104} INFO - Linhas:  20000
[2021-04-07 03:03:16,449] {logging_mixin.py:104} INFO - Colunas:  33
[2021-04-07 03:03:54,009] {logging_mixin.py:104} INFO - entrou no laço
[2021-04-07 03:03:54,024] {logging_mixin.py:104} INFO - Paginas:  100000
[2021-04-07 03:03:54,026] {logging_mixin.py:104} INFO - Contador:  6
[2021-04-07 03:03:54,026] {logging_mixin.py:104} INFO - Linhas:  25000
[2021-04-07 03:03:54,027] {logging_mixin.py:104} INFO - Colunas:  33
[2021-04-07 03:04:31,707] {logging_mixin.py:104} INFO - entrou no laço
[2021-04-07 03:04:31,708] {logging_mixin.py:104} INFO - Paginas:  100000
[2021-04-07 03:04:31,708] {logging_mixin.py:104} INFO - Contador:  7
[2021-04-07 03:04:31,708] {logging_mixin.py:104} INFO - Linhas:  30000
[2021-04-07 03:04:31,708] {logging_mixin.py:104} INFO - Colunas:  33
[2021-04-07 03:05:10,477] {logging_mixin.py:104} INFO - entrou no laço
[2021-04-07 03:05:10,478] {logging_mixin.py:104} INFO - Paginas:  100000
[2021-04-07 03:05:10,478] {logging_mixin.py:104} INFO - Contador:  8
[2021-04-07 03:05:10,479] {logging_mixin.py:104} INFO - Linhas:  35000
[2021-04-07 03:05:10,479] {logging_mixin.py:104} INFO - Colunas:  33
[2021-04-07 03:05:47,113] {logging_mixin.py:104} INFO - entrou no laço
[2021-04-07 03:05:47,117] {logging_mixin.py:104} INFO - Paginas:  100000
[2021-04-07 03:05:47,118] {logging_mixin.py:104} INFO - Contador:  9
[2021-04-07 03:05:47,118] {logging_mixin.py:104} INFO - Linhas:  40000
[2021-04-07 03:05:47,119] {logging_mixin.py:104} INFO - Colunas:  33
[2021-04-07 03:06:26,039] {logging_mixin.py:104} INFO - entrou no laço
[2021-04-07 03:06:26,042] {logging_mixin.py:104} INFO - Paginas:  100000
[2021-04-07 03:06:26,042] {logging_mixin.py:104} INFO - Contador:  10
[2021-04-07 03:06:26,042] {logging_mixin.py:104} INFO - Linhas:  45000
[2021-04-07 03:06:26,043] {logging_mixin.py:104} INFO - Colunas:  33
[2021-04-07 03:07:06,319] {logging_mixin.py:104} INFO - entrou no laço
[2021-04-07 03:07:06,321] {logging_mixin.py:104} INFO - Paginas:  100000
[2021-04-07 03:07:06,325] {logging_mixin.py:104} INFO - Contador:  11
[2021-04-07 03:07:06,327] {logging_mixin.py:104} INFO - Linhas:  50000
[2021-04-07 03:07:06,336] {logging_mixin.py:104} INFO - Colunas:  33
[2021-04-07 03:07:53,933] {logging_mixin.py:104} INFO - entrou no laço
[2021-04-07 03:07:53,934] {logging_mixin.py:104} INFO - Paginas:  100000
[2021-04-07 03:07:53,935] {logging_mixin.py:104} INFO - Contador:  12
[2021-04-07 03:07:53,947] {logging_mixin.py:104} INFO - Linhas:  55000
[2021-04-07 03:07:53,947] {logging_mixin.py:104} INFO - Colunas:  33
[2021-04-07 03:08:39,404] {logging_mixin.py:104} INFO - entrou no laço
[2021-04-07 03:08:39,407] {logging_mixin.py:104} INFO - Paginas:  100000
[2021-04-07 03:08:39,408] {logging_mixin.py:104} INFO - Contador:  13
[2021-04-07 03:08:39,408] {logging_mixin.py:104} INFO - Linhas:  60000
[2021-04-07 03:08:39,409] {logging_mixin.py:104} INFO - Colunas:  33
[2021-04-07 03:08:40,457] {taskinstance.py:1455} ERROR - 'root'
Traceback (most recent call last):
  File "/home/airflow/.local/lib/python3.6/site-packages/airflow/models/taskinstance.py", line 1112, in _run_raw_task
    self._prepare_and_execute_task_with_callbacks(context, task)
  File "/home/airflow/.local/lib/python3.6/site-packages/airflow/models/taskinstance.py", line 1285, in _prepare_and_execute_task_with_callbacks
    result = self._execute_task(context, task_copy)
  File "/home/airflow/.local/lib/python3.6/site-packages/airflow/models/taskinstance.py", line 1315, in _execute_task
    result = task_copy.execute(context=context)
  File "/home/airflow/.local/lib/python3.6/site-packages/airflow/operators/python.py", line 117, in execute
    return_value = self.execute_callable()
  File "/home/airflow/.local/lib/python3.6/site-packages/airflow/operators/python.py", line 128, in execute_callable
    return self.python_callable(*self.op_args, **self.op_kwargs)
  File "/opt/airflow/dags/etl_chamados.py", line 100, in carrega_dados
    root = resp_data['root']
KeyError: 'root'
[2021-04-07 03:08:40,478] {taskinstance.py:1503} INFO - Marking task as FAILED. dag_id=trata_relatorios, task_id=popula_relatorios, execution_date=20210407T025000, start_date=20210407T030001, end_date=20210407T030840
[2021-04-07 03:08:40,586] {configuration.py:356} WARNING - section/key [smtp/smtp_user] not found in config
[2021-04-07 03:08:40,628] {email.py:184} INFO - Email alerting: attempt 1
[2021-04-07 03:08:40,633] {configuration.py:356} WARNING - section/key [smtp/smtp_user] not found in config
[2021-04-07 03:08:40,643] {email.py:184} INFO - Email alerting: attempt 1
[2021-04-07 03:08:40,645] {taskinstance.py:1509} ERROR - Failed to send email to: ['clecio.antao@gmail.com']
[2021-04-07 03:08:40,646] {taskinstance.py:1510} ERROR - [Errno 99] Cannot assign requested address
Traceback (most recent call last):
  File "/home/airflow/.local/lib/python3.6/site-packages/airflow/models/taskinstance.py", line 1112, in _run_raw_task
    self._prepare_and_execute_task_with_callbacks(context, task)
  File "/home/airflow/.local/lib/python3.6/site-packages/airflow/models/taskinstance.py", line 1285, in _prepare_and_execute_task_with_callbacks
    result = self._execute_task(context, task_copy)
  File "/home/airflow/.local/lib/python3.6/site-packages/airflow/models/taskinstance.py", line 1315, in _execute_task
    result = task_copy.execute(context=context)
  File "/home/airflow/.local/lib/python3.6/site-packages/airflow/operators/python.py", line 117, in execute
    return_value = self.execute_callable()
  File "/home/airflow/.local/lib/python3.6/site-packages/airflow/operators/python.py", line 128, in execute_callable
    return self.python_callable(*self.op_args, **self.op_kwargs)
  File "/opt/airflow/dags/etl_chamados.py", line 100, in carrega_dados
    root = resp_data['root']
KeyError: 'root'

During handling of the above exception, another exception occurred:

Traceback (most recent call last):
  File "/home/airflow/.local/lib/python3.6/site-packages/airflow/models/taskinstance.py", line 1852, in email_alert
    send_email(self.task.email, subject, html_content)
  File "/home/airflow/.local/lib/python3.6/site-packages/airflow/utils/email.py", line 62, in send_email
    **kwargs,
  File "/home/airflow/.local/lib/python3.6/site-packages/airflow/utils/email.py", line 97, in send_email_smtp
    send_mime_email(e_from=smtp_mail_from, e_to=recipients, mime_msg=msg, dryrun=dryrun)
  File "/home/airflow/.local/lib/python3.6/site-packages/airflow/utils/email.py", line 186, in send_mime_email
    conn = _get_smtp_connection(smtp_host, smtp_port, smtp_timeout, smtp_ssl)
  File "/home/airflow/.local/lib/python3.6/site-packages/airflow/utils/email.py", line 220, in _get_smtp_connection
    else smtplib.SMTP(host=host, port=port, timeout=timeout)
  File "/usr/local/lib/python3.6/smtplib.py", line 251, in __init__
    (code, msg) = self.connect(host, port)
  File "/usr/local/lib/python3.6/smtplib.py", line 336, in connect
    self.sock = self._get_socket(host, port, self.timeout)
  File "/usr/local/lib/python3.6/smtplib.py", line 307, in _get_socket
    self.source_address)
  File "/usr/local/lib/python3.6/socket.py", line 724, in create_connection
    raise err
  File "/usr/local/lib/python3.6/socket.py", line 713, in create_connection
    sock.connect(sa)
OSError: [Errno 99] Cannot assign requested address

During handling of the above exception, another exception occurred:

Traceback (most recent call last):
  File "/home/airflow/.local/lib/python3.6/site-packages/airflow/models/taskinstance.py", line 1507, in handle_failure
    self.email_alert(error)
  File "/home/airflow/.local/lib/python3.6/site-packages/airflow/models/taskinstance.py", line 1854, in email_alert
    send_email(self.task.email, subject, html_content_err)
  File "/home/airflow/.local/lib/python3.6/site-packages/airflow/utils/email.py", line 62, in send_email
    **kwargs,
  File "/home/airflow/.local/lib/python3.6/site-packages/airflow/utils/email.py", line 97, in send_email_smtp
    send_mime_email(e_from=smtp_mail_from, e_to=recipients, mime_msg=msg, dryrun=dryrun)
  File "/home/airflow/.local/lib/python3.6/site-packages/airflow/utils/email.py", line 186, in send_mime_email
    conn = _get_smtp_connection(smtp_host, smtp_port, smtp_timeout, smtp_ssl)
  File "/home/airflow/.local/lib/python3.6/site-packages/airflow/utils/email.py", line 220, in _get_smtp_connection
    else smtplib.SMTP(host=host, port=port, timeout=timeout)
  File "/usr/local/lib/python3.6/smtplib.py", line 251, in __init__
    (code, msg) = self.connect(host, port)
  File "/usr/local/lib/python3.6/smtplib.py", line 336, in connect
    self.sock = self._get_socket(host, port, self.timeout)
  File "/usr/local/lib/python3.6/smtplib.py", line 307, in _get_socket
    self.source_address)
  File "/usr/local/lib/python3.6/socket.py", line 724, in create_connection
    raise err
  File "/usr/local/lib/python3.6/socket.py", line 713, in create_connection
    sock.connect(sa)
OSError: [Errno 99] Cannot assign requested address
[2021-04-07 03:08:40,876] {local_task_job.py:146} INFO - Task exited with return code 1
